        <mujoco model="ff_master_bricklaying_process">
          <include file="ff_master_ultra.xml"/>
          <option integrator="Euler" solver="CG" iterations="80" tolerance="1e-8"/>

          <statistic center="0.55 0 0.7" extent="1.4"/>
          <visual>
            <headlight diffuse="0.7 0.7 0.7" ambient="0.25 0.25 0.25" specular="0.4 0.4 0.4"/>
            <global azimuth="125" elevation="-18" offwidth="1280" offheight="720"/>
          </visual>

          <asset>
            <texture name="site_grid" type="2d" builtin="checker" rgb1="0.36 0.37 0.33" rgb2="0.27 0.29 0.27" width="512" height="512"/>
            <material name="floor_mat" texture="site_grid" texrepeat="7 7" reflectance="0.08"/>
            <material name="brick_mat" rgba="0.66 0.24 0.14 1"/>
            <material name="mortar_mat" rgba="0.78 0.75 0.67 1"/>
            <material name="guide_mat" rgba="0.92 0.82 0.55 0.24"/>
            <material name="pallet_mat" rgba="0.38 0.26 0.14 1"/>
            <material name="tray_mat" rgba="0.22 0.23 0.22 1"/>
          </asset>

          <worldbody>
            <geom name="construction_floor" type="plane" size="2.2 2.2 0.05" material="floor_mat"/>
            <light name="work_light" pos="0 -1.5 2.8" dir="0 0 -1" diffuse="0.8 0.8 0.75"/>
            <camera name="bricklaying_overview" pos="-0.75 -2.75 1.65" xyaxes="0.97 -0.24 0 0.13 0.53 0.84" fovy="58"/>
            <camera name="hand_closeup" pos="-0.45 -1.22 0.58" xyaxes="0.99 -0.13 0 0.04 0.31 0.95" fovy="42"/>

            <body name="brick_pallet" pos="-0.3 -1.25 0.025">
              <geom type="box" size="0.42 0.12 0.025" material="pallet_mat"/>
            </body>
            <body name="mortar_tray" pos="-0.08 -0.92 0.02">
              <geom type="box" size="0.24 0.15 0.02" material="tray_mat"/>
            </body>
            <body name="mortar_bed" pos="-0.08 -0.92 0.052000000000000005">
              <geom type="box" size="0.2 0.1 0.012" material="mortar_mat"/>
            </body>
            <body name="wall_course_guide" pos="0.72 -0.24 -0.01">
              <geom type="box" size="0.12420000000000002 0.36 0.01" material="guide_mat"/>
            </body>

<body name="right_tool_hand" pos="0 0 -0.5">
  <freejoint name="right_tool_hand_free"/>
  <geom name="right_tool_palm" type="box" size="0.045 0.044 0.015" rgba="0.18 0.19 0.2 1"/>

    <body name="right_tool_thumb_base" pos="0.075 -0.035 -0.008" euler="0 0 -0.3">
      <joint name="right_hand_thumb_0_joint" type="hinge" axis="0 1 0" range="-0.75 0.75" damping="0.08"/>
      <geom name="right_tool_thumb_proximal" type="capsule" fromto="0 0 0 0.055 0 0" size="0.009" rgba="0.92 0.92 0.88 1"/>
      <body name="right_tool_thumb_tip" pos="0.055 0 0">
        <joint name="right_hand_thumb_1_joint" type="hinge" axis="0 1 0" range="-0.9 0.9" damping="0.08"/>
        <geom name="right_tool_thumb_distal" type="capsule" fromto="0 0 0 0.039599999999999996 0 0" size="0.007" rgba="0.96 0.82 0.58 1"/>

        <body name="right_tool_thumb_pad" pos="0.039599999999999996 0 0">
          <joint name="right_hand_thumb_2_joint" type="hinge" axis="0 1 0" range="-0.9 0.9" damping="0.08"/>
          <geom name="right_tool_thumb_pad" type="capsule" fromto="0 0 0 0.0264 0 0" size="0.006" rgba="0.96 0.82 0.58 1"/>
        </body>

      </body>
    </body>

    <body name="right_tool_index_base" pos="0.075 -0.014 -0.008" euler="0 0 0.0">
      <joint name="right_hand_index_0_joint" type="hinge" axis="0 1 0" range="-0.75 0.75" damping="0.08"/>
      <geom name="right_tool_index_proximal" type="capsule" fromto="0 0 0 0.026 0 0" size="0.009" rgba="0.92 0.92 0.88 1"/>
      <body name="right_tool_index_tip" pos="0.026 0 0">
        <joint name="right_hand_index_1_joint" type="hinge" axis="0 1 0" range="-0.9 0.9" damping="0.08"/>
        <geom name="right_tool_index_distal" type="capsule" fromto="0 0 0 0.018719999999999997 0 0" size="0.007" rgba="0.96 0.82 0.58 1"/>

      </body>
    </body>

    <body name="right_tool_middle_base" pos="0.075 0.014 -0.008" euler="0 0 0.0">
      <joint name="right_hand_middle_0_joint" type="hinge" axis="0 1 0" range="-0.75 0.75" damping="0.08"/>
      <geom name="right_tool_middle_proximal" type="capsule" fromto="0 0 0 0.026 0 0" size="0.009" rgba="0.92 0.92 0.88 1"/>
      <body name="right_tool_middle_tip" pos="0.026 0 0">
        <joint name="right_hand_middle_1_joint" type="hinge" axis="0 1 0" range="-0.9 0.9" damping="0.08"/>
        <geom name="right_tool_middle_distal" type="capsule" fromto="0 0 0 0.018719999999999997 0 0" size="0.007" rgba="0.96 0.82 0.58 1"/>

      </body>
    </body>

    <body name="right_tool_ring_base" pos="0.075 0.039 -0.008" euler="0 0 0.12">
      <joint name="right_hand_ring_0_joint" type="hinge" axis="0 1 0" range="-0.75 0.75" damping="0.08"/>
      <geom name="right_tool_ring_proximal" type="capsule" fromto="0 0 0 0.022 0 0" size="0.009" rgba="0.92 0.92 0.88 1"/>
      <body name="right_tool_ring_tip" pos="0.022 0 0">
        <joint name="right_hand_ring_1_joint" type="hinge" axis="0 1 0" range="-0.9 0.9" damping="0.08"/>
        <geom name="right_tool_ring_distal" type="capsule" fromto="0 0 0 0.01584 0 0" size="0.007" rgba="0.96 0.82 0.58 1"/>

      </body>
    </body>

</body>

            <body name="brick_00" pos="-0.3 -1.1899999999999997 0.11"><freejoint name="brick_00_free"/><geom name="brick_00_geom" type="box" size="0.115 0.055 0.06" material="brick_mat" mass="2.2" contype="0" conaffinity="0"/></body>
<body name="brick_01" pos="-0.5700000000000001 -1.1899999999999997 0.11"><freejoint name="brick_01_free"/><geom name="brick_01_geom" type="box" size="0.115 0.055 0.06" material="brick_mat" mass="2.2" contype="0" conaffinity="0"/></body>
<body name="brick_02" pos="-0.02999999999999997 -1.1899999999999997 0.11"><freejoint name="brick_02_free"/><geom name="brick_02_geom" type="box" size="0.115 0.055 0.06" material="brick_mat" mass="2.2" contype="0" conaffinity="0"/></body>
<body name="brick_03" pos="-0.3 -1.1899999999999997 0.242"><freejoint name="brick_03_free"/><geom name="brick_03_geom" type="box" size="0.115 0.055 0.06" material="brick_mat" mass="2.2" contype="0" conaffinity="0"/></body>
            <body name="mortar_00_first_side" pos="0.0 0.0 -0.4"><freejoint name="mortar_00_first_side_free"/><geom name="mortar_00_first_side_geom" type="box" size="0.006 0.0473 0.0456" material="mortar_mat" mass="0.01" contype="0" conaffinity="0"/></body>
<body name="mortar_00_second_side" pos="0.0 0.0 -0.45"><freejoint name="mortar_00_second_side_free"/><geom name="mortar_00_second_side_geom" type="box" size="0.006 0.0473 0.0456" material="mortar_mat" mass="0.01" contype="0" conaffinity="0"/></body>
<body name="mortar_01_first_side" pos="0.0 0.0 -0.5"><freejoint name="mortar_01_first_side_free"/><geom name="mortar_01_first_side_geom" type="box" size="0.006 0.0473 0.0456" material="mortar_mat" mass="0.01" contype="0" conaffinity="0"/></body>
<body name="mortar_01_second_side" pos="0.0 0.0 -0.55"><freejoint name="mortar_01_second_side_free"/><geom name="mortar_01_second_side_geom" type="box" size="0.006 0.0473 0.0456" material="mortar_mat" mass="0.01" contype="0" conaffinity="0"/></body>
<body name="mortar_02_first_side" pos="0.0 0.0 -0.6000000000000001"><freejoint name="mortar_02_first_side_free"/><geom name="mortar_02_first_side_geom" type="box" size="0.006 0.0473 0.0456" material="mortar_mat" mass="0.01" contype="0" conaffinity="0"/></body>
<body name="mortar_02_second_side" pos="0.0 0.0 -0.65"><freejoint name="mortar_02_second_side_free"/><geom name="mortar_02_second_side_geom" type="box" size="0.006 0.0473 0.0456" material="mortar_mat" mass="0.01" contype="0" conaffinity="0"/></body>
<body name="mortar_03_first_side" pos="0.0 0.0 -0.7000000000000001"><freejoint name="mortar_03_first_side_free"/><geom name="mortar_03_first_side_geom" type="box" size="0.006 0.0473 0.0456" material="mortar_mat" mass="0.01" contype="0" conaffinity="0"/></body>
<body name="mortar_03_second_side" pos="0.0 0.0 -0.75"><freejoint name="mortar_03_second_side_free"/><geom name="mortar_03_second_side_geom" type="box" size="0.006 0.0473 0.0456" material="mortar_mat" mass="0.01" contype="0" conaffinity="0"/></body>
          </worldbody>
          <actuator>
            <position name="right_hand_thumb_0_joint" joint="right_hand_thumb_0_joint" kp="12" dampratio="1" ctrlrange="-0.9 0.9"/>
<position name="right_hand_thumb_1_joint" joint="right_hand_thumb_1_joint" kp="12" dampratio="1" ctrlrange="-0.9 0.9"/>
<position name="right_hand_thumb_2_joint" joint="right_hand_thumb_2_joint" kp="12" dampratio="1" ctrlrange="-0.9 0.9"/>
<position name="right_hand_index_0_joint" joint="right_hand_index_0_joint" kp="12" dampratio="1" ctrlrange="-0.9 0.9"/>
<position name="right_hand_index_1_joint" joint="right_hand_index_1_joint" kp="12" dampratio="1" ctrlrange="-0.9 0.9"/>
<position name="right_hand_middle_0_joint" joint="right_hand_middle_0_joint" kp="12" dampratio="1" ctrlrange="-0.9 0.9"/>
<position name="right_hand_middle_1_joint" joint="right_hand_middle_1_joint" kp="12" dampratio="1" ctrlrange="-0.9 0.9"/>
<position name="right_hand_ring_0_joint" joint="right_hand_ring_0_joint" kp="12" dampratio="1" ctrlrange="-0.9 0.9"/>
<position name="right_hand_ring_1_joint" joint="right_hand_ring_1_joint" kp="12" dampratio="1" ctrlrange="-0.9 0.9"/>
          </actuator>
        </mujoco>
